{
  "Header": {
    "Original": "CVE-2020-14343 (A vulnerability was discovered in the PyYAML library in versions befor ...)",
    "Line": 291188,
    "ID": "CVE-2020-14343",
    "Description": "(A vulnerability was discovered in the PyYAML library in versions befor ...)"
  },
  "Annotations": [
    {
      "Original": "- pyyaml 5.3.1-4 (bug #966233)",
      "Line": 291189,
      "Type": "package",
      "Package": "pyyaml",
      "Kind": "fixed",
      "Version": "5.3.1-4",
      "BugNo": 966233
    },
    {
      "Original": "[buster] - pyyaml \u003cnot-affected\u003e (Vulnerable code not present)",
      "Line": 291190,
      "Type": "package",
      "Release": "buster",
      "Package": "pyyaml",
      "Kind": "not-affected",
      "Description": "Vulnerable code not present"
    },
    {
      "Original": "[stretch] - pyyaml \u003cnot-affected\u003e (Vulnerable code not present)",
      "Line": 291191,
      "Type": "package",
      "Release": "stretch",
      "Package": "pyyaml",
      "Kind": "not-affected",
      "Description": "Vulnerable code not present"
    },
    {
      "Original": "NOTE: https://github.com/yaml/pyyaml/issues/420",
      "Line": 291192,
      "Type": "NOTE",
      "Description": "https://github.com/yaml/pyyaml/issues/420"
    },
    {
      "Original": "NOTE: Fixed via: https://github.com/yaml/pyyaml/pull/472",
      "Line": 291193,
      "Type": "NOTE",
      "Description": "Fixed via: https://github.com/yaml/pyyaml/pull/472"
    },
    {
      "Original": "NOTE: https://github.com/yaml/pyyaml/commit/7adc0db3f613a82669f2b168edd98379b83adb3c",
      "Line": 291194,
      "Type": "NOTE",
      "Description": "https://github.com/yaml/pyyaml/commit/7adc0db3f613a82669f2b168edd98379b83adb3c"
    },
    {
      "Original": "NOTE: CVE is for an incomplete fix of CVE-2020-1747.",
      "Line": 291195,
      "Type": "NOTE",
      "Description": "CVE is for an incomplete fix of CVE-2020-1747."
    }
  ]
}