{
  "Header": {
    "Original": "CVE-2021-3572 (A flaw was found in python-pip in the way it handled Unicode separator ...)",
    "Line": 210755,
    "ID": "CVE-2021-3572",
    "Description": "(A flaw was found in python-pip in the way it handled Unicode separator ...)"
  },
  "Annotations": [
    {
      "Original": "- python-pip 20.3.4-2",
      "Line": 210756,
      "Type": "package",
      "Package": "python-pip",
      "Kind": "fixed",
      "Version": "20.3.4-2"
    },
    {
      "Original": "[buster] - python-pip \u003cno-dsa\u003e (Minor issue)",
      "Line": 210757,
      "Type": "package",
      "Release": "buster",
      "Package": "python-pip",
      "Kind": "no-dsa",
      "Description": "Minor issue"
    },
    {
      "Original": "[stretch] - python-pip \u003cpostponed\u003e (Minor issue. Fix along with next DLA)",
      "Line": 210758,
      "Type": "package",
      "Release": "stretch",
      "Package": "python-pip",
      "Kind": "postponed",
      "Description": "Minor issue. Fix along with next DLA"
    },
    {
      "Original": "NOTE: https://bugs.launchpad.net/ubuntu/+source/python-pip/+bug/1926957",
      "Line": 210759,
      "Type": "NOTE",
      "Description": "https://bugs.launchpad.net/ubuntu/+source/python-pip/+bug/1926957"
    },
    {
      "Original": "NOTE: https://github.com/pypa/pip/pull/9827",
      "Line": 210760,
      "Type": "NOTE",
      "Description": "https://github.com/pypa/pip/pull/9827"
    },
    {
      "Original": "NOTE: https://github.com/pypa/pip/commit/ca832b2836e0bffa7cf95589acdcd71230f5834e (21.1)",
      "Line": 210761,
      "Type": "NOTE",
      "Description": "https://github.com/pypa/pip/commit/ca832b2836e0bffa7cf95589acdcd71230f5834e (21.1)"
    }
  ]
}