{
  "Header": {
    "Original": "CVE-2021-31542 (In Django 2.2 before 2.2.21, 3.1 before 3.1.9, and 3.2 before 3.2.1, M ...)",
    "Line": 198799,
    "ID": "CVE-2021-31542",
    "Description": "(In Django 2.2 before 2.2.21, 3.1 before 3.1.9, and 3.2 before 3.2.1, M ...)"
  },
  "Annotations": [
    {
      "Original": "{DLA-2651-1}",
      "Line": 198800,
      "Type": "xref",
      "Bugs": [
        "DLA-2651-1"
      ]
    },
    {
      "Original": "- python-django 2:2.2.21-1 (bug #988053)",
      "Line": 198801,
      "Type": "package",
      "Package": "python-django",
      "Kind": "fixed",
      "Version": "2:2.2.21-1",
      "BugNo": 988053
    },
    {
      "Original": "[buster] - python-django \u003cno-dsa\u003e (Minor issue)",
      "Line": 198802,
      "Type": "package",
      "Release": "buster",
      "Package": "python-django",
      "Kind": "no-dsa",
      "Description": "Minor issue"
    },
    {
      "Original": "NOTE: https://www.djangoproject.com/weblog/2021/may/04/security-releases/",
      "Line": 198803,
      "Type": "NOTE",
      "Description": "https://www.djangoproject.com/weblog/2021/may/04/security-releases/"
    },
    {
      "Original": "NOTE: https://github.com/django/django/commit/0b79eb36915d178aef5c6a7bbce71b1e76d376d3 (main)",
      "Line": 198804,
      "Type": "NOTE",
      "Description": "https://github.com/django/django/commit/0b79eb36915d178aef5c6a7bbce71b1e76d376d3 (main)"
    },
    {
      "Original": "NOTE: https://github.com/django/django/commit/04ac1624bdc2fa737188401757cf95ced122d26d (2.2.21)",
      "Line": 198805,
      "Type": "NOTE",
      "Description": "https://github.com/django/django/commit/04ac1624bdc2fa737188401757cf95ced122d26d (2.2.21)"
    }
  ]
}