{
  "affected_release": null,
  "package_state": [
    {
      "product_name": "Red Hat Enterprise Linux 6",
      "fix_state": "Not affected",
      "package_name": "python",
      "cpe": "cpe:/o:redhat:enterprise_linux:6"
    },
    {
      "product_name": "Red Hat Enterprise Linux 7",
      "fix_state": "Not affected",
      "package_name": "python",
      "cpe": "cpe:/o:redhat:enterprise_linux:7"
    },
    {
      "product_name": "Red Hat Enterprise Linux 7",
      "fix_state": "Not affected",
      "package_name": "python3",
      "cpe": "cpe:/o:redhat:enterprise_linux:7"
    },
    {
      "product_name": "Red Hat Enterprise Linux 8",
      "fix_state": "Not affected",
      "package_name": "gimp:flatpak/python2",
      "cpe": "cpe:/o:redhat:enterprise_linux:8"
    },
    {
      "product_name": "Red Hat Enterprise Linux 8",
      "fix_state": "Not affected",
      "package_name": "inkscape:flatpak/python2",
      "cpe": "cpe:/o:redhat:enterprise_linux:8"
    },
    {
      "product_name": "Red Hat Enterprise Linux 8",
      "fix_state": "Not affected",
      "package_name": "python27:2.7/python2",
      "cpe": "cpe:/o:redhat:enterprise_linux:8"
    },
    {
      "product_name": "Red Hat Enterprise Linux 8",
      "fix_state": "Not affected",
      "package_name": "python3",
      "cpe": "cpe:/o:redhat:enterprise_linux:8"
    },
    {
      "product_name": "Red Hat Enterprise Linux 8",
      "fix_state": "Not affected",
      "package_name": "python3.11",
      "cpe": "cpe:/o:redhat:enterprise_linux:8"
    },
    {
      "product_name": "Red Hat Enterprise Linux 8",
      "fix_state": "Not affected",
      "package_name": "python3.12",
      "cpe": "cpe:/o:redhat:enterprise_linux:8"
    },
    {
      "product_name": "Red Hat Enterprise Linux 8",
      "fix_state": "Not affected",
      "package_name": "python36:3.6/python36",
      "cpe": "cpe:/o:redhat:enterprise_linux:8"
    },
    {
      "product_name": "Red Hat Enterprise Linux 8",
      "fix_state": "Not affected",
      "package_name": "python39:3.9/python39",
      "cpe": "cpe:/o:redhat:enterprise_linux:8"
    },
    {
      "product_name": "Red Hat Enterprise Linux 8",
      "fix_state": "Not affected",
      "package_name": "python39-devel:3.9/python39",
      "cpe": "cpe:/o:redhat:enterprise_linux:8"
    },
    {
      "product_name": "Red Hat Enterprise Linux 9",
      "fix_state": "Not affected",
      "package_name": "python3.11",
      "cpe": "cpe:/o:redhat:enterprise_linux:9"
    },
    {
      "product_name": "Red Hat Enterprise Linux 9",
      "fix_state": "Not affected",
      "package_name": "python3.12",
      "cpe": "cpe:/o:redhat:enterprise_linux:9"
    },
    {
      "product_name": "Red Hat Enterprise Linux 9",
      "fix_state": "Not affected",
      "package_name": "python3.9",
      "cpe": "cpe:/o:redhat:enterprise_linux:9"
    }
  ],
  "threat_severity": "Moderate",
  "public_date": "2023-12-08T00:00:00Z",
  "bugzilla": {
    "description": "python: Improper privileges drop on subprocess module",
    "id": "2293948",
    "url": "https://bugzilla.redhat.com/show_bug.cgi?id=2293948"
  },
  "cvss": {
    "cvss_base_score": "",
    "cvss_scoring_vector": "",
    "status": ""
  },
  "cvss3": {
    "cvss3_base_score": "6.1",
    "cvss3_scoring_vector": "CVSS:3.1/AV:A/AC:L/PR:H/UI:N/S:U/C:H/I:H/A:N",
    "status": "draft"
  },
  "iava": "",
  "cwe": "CWE-269",
  "statement": "The Python versions as distributed with Red Hat Enterprise Linux 6, 7, 8 and 9 are not vulnerable to this flaw, as it doesn't contain the affected code or it ships a version where the fix is already present.",
  "acknowledgement": "",
  "name": "CVE-2023-6507",
  "document_distribution": "",
  "details": [
    "An issue was found in CPython 3.12.0 `subprocess` module on POSIX platforms. The issue was fixed in CPython 3.12.1 and does not affect other stable releases.\nWhen using the `extra_groups=` parameter with an empty list as a value (ie `extra_groups=[]`) the logic regressed to not call `setgroups(0, NULL)` before calling `exec()`, thus not dropping the original processes' groups before starting the new process. There is no issue when the parameter isn't used or when any value is used besides an empty list.\nThis issue only impacts CPython processes run with sufficient privilege to make the `setgroups` system call (typically `root`).",
    "A flaw was found in Python's subprocess module. When creating a new subprocess, the developer may specify a list of extra groups through the 'extra_groups=` parameter. When this optional parameter is informed with an empty list, the module fails to properly clean the associated groups from the new sub-process's parent before executing the new sub-process. If the parent process has high privileges, the sub-process created may have unnecessarily high privileges, leading to possible confidentiality and integrity issues when properly exploited."
  ],
  "references": [
    "https://www.cve.org/CVERecord?id=CVE-2023-6507\nhttps://nvd.nist.gov/vuln/detail/CVE-2023-6507"
  ]
}