{
  "affected_release": [
    {
      "product_name": "Red Hat OpenStack Platform 13.0 (Queens)",
      "release_date": "2019-01-16T00:00:00Z",
      "advisory": "RHSA-2019:0085",
      "package": "pyOpenSSL-0:17.5.0-1.el7ost",
      "cpe": "cpe:/a:redhat:openstack:13::el7"
    }
  ],
  "package_state": [
    {
      "product_name": "Red Hat Enterprise Linux 5",
      "fix_state": "Not affected",
      "package_name": "pyOpenSSL",
      "cpe": "cpe:/o:redhat:enterprise_linux:5"
    },
    {
      "product_name": "Red Hat Enterprise Linux 6",
      "fix_state": "Not affected",
      "package_name": "pyOpenSSL",
      "cpe": "cpe:/o:redhat:enterprise_linux:6"
    },
    {
      "product_name": "Red Hat Enterprise Linux 7",
      "fix_state": "Not affected",
      "package_name": "pyOpenSSL",
      "cpe": "cpe:/o:redhat:enterprise_linux:7"
    },
    {
      "product_name": "Red Hat Enterprise Linux 8",
      "fix_state": "Not affected",
      "package_name": "pyOpenSSL",
      "cpe": "cpe:/o:redhat:enterprise_linux:8"
    },
    {
      "product_name": "Red Hat OpenStack Platform 10 (Newton)",
      "fix_state": "Will not fix",
      "package_name": "pyOpenSSL",
      "cpe": "cpe:/a:redhat:openstack:10"
    },
    {
      "product_name": "Red Hat OpenStack Platform 12 (Pike)",
      "fix_state": "Will not fix",
      "package_name": "pyOpenSSL",
      "cpe": "cpe:/a:redhat:openstack:12"
    },
    {
      "product_name": "Red Hat OpenStack Platform 14 (Rocky)",
      "fix_state": "Not affected",
      "package_name": "pyOpenSSL",
      "cpe": "cpe:/a:redhat:openstack:14"
    },
    {
      "product_name": "Red Hat Storage 3",
      "fix_state": "Will not fix",
      "package_name": "pyOpenSSL",
      "cpe": "cpe:/a:redhat:storage:3"
    },
    {
      "product_name": "Red Hat Virtualization 4",
      "fix_state": "Will not fix",
      "package_name": "pyOpenSSL",
      "cpe": "cpe:/a:redhat:enterprise_linux:8::hypervisor"
    }
  ],
  "threat_severity": "Moderate",
  "public_date": "2017-11-29T00:00:00Z",
  "bugzilla": {
    "description": "pyOpenSSL: Use-after-free in X509 object handling",
    "id": "1640217",
    "url": "https://bugzilla.redhat.com/show_bug.cgi?id=1640217"
  },
  "cvss": {
    "cvss_base_score": "",
    "cvss_scoring_vector": "",
    "status": ""
  },
  "cvss3": {
    "cvss3_base_score": "8.1",
    "cvss3_scoring_vector": "CVSS:3.0/AV:N/AC:H/PR:N/UI:N/S:U/C:H/I:H/A:H",
    "status": "verified"
  },
  "iava": "",
  "cwe": "CWE-416",
  "statement": "This vulnerability is only present when a specific and uncommon usage pattern of pyOpenSSL occurs. Red Hat Product Security has audited our packages that use pyOpenSSL, and determined that software we distribute in Red Hat Enterprise Linux and Red Hat Virtualization does not use pyOpenSSL in such a way as to be vulnerable. Future updates may address this issue.",
  "acknowledgement": "",
  "name": "CVE-2018-1000807",
  "document_distribution": "",
  "details": [
    "Python Cryptographic Authority pyopenssl version prior to version 17.5.0 contains a CWE-416: Use After Free vulnerability in X509 object handling that can result in Use after free can lead to possible denial of service or remote code execution.. This attack appear to be exploitable via Depends on the calling application and if it retains a reference to the memory.. This vulnerability appears to have been fixed in 17.5.0."
  ],
  "references": [
    "https://www.cve.org/CVERecord?id=CVE-2018-1000807\nhttps://nvd.nist.gov/vuln/detail/CVE-2018-1000807"
  ]
}